Workbook

Sheet Свод
A1: ИД мероприятия | B1: ИД значения результата | C1: Наименование мероприятия | D1: Описательная часть характеристики | E1: Подпись план | F1: Подпись факт | G1: Подпись подтверждение | H1: Корректно по предыдущему статусу ЦПМ | I1: Прошлый статус | J1: Прошлый анализ | K1: ЦПМ корректность статуса ИИ | L1: ЦПМ корректность анализа ИИ | M1: ЦПМ Полный комментарий | N1: Характеристика план | O1: Характеристика факт | P1: Характеристика подтверждение | Q1: Корректно по предыдущему статусу ЦПМ | R1: Прошлый статус | S1: Прошлый анализ | T1: ЦПМ корректность статуса ИИ | U1: ЦПМ корректность анализа ИИ | V1: ЦПМ Полный комментарий | W1: ПХР план | X1: ПХР факт | Y1: ПХР подтверждение | Z1: Корректно по предыдущему статусу ЦПМ | AA1: Прошлый статус | AB1: Прошлый анализ | AC1: ЦПМ корректность статуса ИИ | AD1: ЦПМ корректность анализа ИИ | AE1: ЦПМ Полный комментарий | AF1: Результат план | AG1: Результат единица | AH1: Результат факт | AI1: Результат подтверждение | AJ1: Корректно по предыдущему статусу ЦПМ | AK1: Прошлый статус | AL1: Прошлый анализ | AM1: ЦПМ корректность статуса ИИ | AN1: ЦПМ корректность анализа ИИ | AO1: ЦПМ Полный комментарий
A2: 9351223676 | B2: 9351225755 | C2: Переведены сведения, содержащиеся в реестре требований, в машиночитаемый и машинопонимаемый формат | D2: Выполнены работы по переводу сведений, содержащихся в реестре требований, подлежащих применению при выполнении инженерных изысканий, осуществлении архитектурно-строительного проектирования, проведении экспертизы проектной документации и (или) экспертизы результатов инженерных изысканий, строительстве, реконструкции, капитальном ремонте, эксплуатации и сносе объектов капитального строительства, в машиночитаемый и машинопонимаемый формат и переработке нормативных требований в принципиально новой форме логических условий, возможной для интерпретации компьютерной техники, и детального перевода всего документа в код, пригодный для использования компьютером без предварительной обработки. | E2: =VLOOKUP(B2,Подпись!$A$1:$E$100,5,0) -> Музыченко Сергей Григорьевич - Заместитель Министра, Файзуллин Ирек Энварович, Ломакин Александр Николаевич, Муценек Юрий Петрович, Стасишин Никита Евгеньевич, Гордеев Юрий Сергеевич, Музыченко Сергей Григорьевич, Михайлик Константин Александрович, Ересько Алексей Васильевич, Леонов Валерий Владимирович, Хусаинов Алмаз Шаукатович | F2: =VLOOKUP(B2,Подпись!$A$1:$E$100,2,0) -> Михайлик Константин Александрович | G2: Подтверждено | H2: {=_xlfn.IFS(AND(G2=I2,K2="нет"),"нет",AND(G2=I2,K2="да"),"да",AND(G2<>I2,K2="нет"),"да",AND(G2<>I2,K2="да"),"нет")} -> нет | I2: =VLOOKUP(B2,'Старый ИИ'!A:AQ,3,FALSE) -> Не подтверждено | J2: =VLOOKUP(B2,'Старый ИИ'!A:AQ,5,FALSE) -> Ошибка анализа: ошибка анализа | K2: =VLOOKUP(B2,'Старый ИИ'!A:AQ,6,FALSE) -> да | L2: =VLOOKUP(B2,'Старый ИИ'!A:AQ,7,FALSE) -> нет | M2: =VLOOKUP(B2,'Старый ИИ'!A:AQ,8,FALSE) -> ИИ корректно не принимает мероприятие - так как в документах стоит подпись не ответственного исполнителя, но в обосновании пишет о технической ошибке. Нет корректного обоснования какие подписи найдены. | N2: Выполнены работы по переводу сведений, содержащихся в реестре требований, подлежащих применению при выполнении инженерных изысканий, осуществлении архитектурно-строительного проектирования, проведении экспертизы проектной документации и (или) экспертизы результатов инженерных изысканий, строительстве, реконструкции, капитальном ремонте, эксплуатации и сносе объектов капитального строительства, в машиночитаемый и машинопонимаемый формат и переработке нормативных требований в принципиально новой форме логических условий, возможной для интерпретации компьютерной техники, и детального перевода всего документа в код, пригодный для использования компьютером без предварительной обработки. | O2: =VLOOKUP(A2,Характеристика!$A$1:$D$100,2,0) -> Подтверждающие сведения 1.pdf - Документ описывает подготовку нормативных и технических требований в машиночитаемом и машинопонимаемом форматах (XML). Это напрямую соответствует цели события по переводу сведений из реестра требований в машиночитаемый формат. Упоминается апробация требований в специализированном ПО, что подтверждает выполнение работ. Подтверждающие сведения 2.pdf - Документ подтверждает достижение показателя федерального проекта по созданию подсистем для перевода Реестра требований в машиночитаемый и машинопонимаемый форматы. Это напрямую соответствует цели события, описанного как перевод сведений из реестра требований в машиночитаемый формат. Упоминание о готовности функционала подсистемы «Реестр требований» подтверждает выполнение работ. | P2: =VLOOKUP(A2,Характеристика!$A$1:$D$100,4,0) -> Подтверждено | Q2: {=_xlfn.IFS(AND(P2=R2,T2="нет"),"нет",AND(P2=R2,T2="да"),"да",AND(P2<>R2,T2="нет"),"да",AND(P2<>R2,T2="да"),"нет")} -> да | R2: =VLOOKUP(B2,'Старый ИИ'!A:AQ,9,FALSE) -> Подтверждено | S2: =VLOOKUP(B2,'Старый ИИ'!A:AQ,11,FALSE) -> Отчет подтверждает выполнение мероприятия: на странице 1 указано достижение результата «Перевод Реестра требований в машиночитаемый и машинопонимаемый форматы» (1 штука). На странице 3 и 4 описаны испытания и готовность подсистемы «Реестр требований» к ввод‑у в опытную эксплуатацию, что свидетельствует о завершённом переводе данных в требуемый формат. | T2: =VLOOKUP(B2,'Старый ИИ'!A:AQ,12,FALSE) -> да | U2: =VLOOKUP(B2,'Старый ИИ'!A:AQ,13,FALSE) -> да | V2: =VLOOKUP(B2,'Старый ИИ'!A:AQ,14,FALSE) -> - | W2: =VLOOKUP(B2,'ПХР актуальный'!$A$1:$C$34,3,0) -> #NUM! | X2: =VLOOKUP(B2,'Результат и ПХР'!$A$1:$Q$992,14,0) -> Проверка опиралась на summary документа "Подтверждающие сведения 1.pdf". В выбранном evidence для метрики "Количество созданных и/или развиваемых подсистем в целях перевода Реестра требований в машиночитаемый и машинопонимаемый форматы" установлено, что характеристика объекта не подтверждена явно; количество не привязано к объекту метрики. Имеющийся фрагмент "100 требований в формате XML подготовлены и успешно апробированы в специализированном ПО" не дает прямого подтверждения выполнения. По правилу fail-closed статус ПХР установлен как "не подтверждено". | Y2: =VLOOKUP(B2,'Результат и ПХР'!$A$1:$Q$992,7,0) -> не подтверждено | Z2: {=_xlfn.IFS(AND(Y2=AA2,AC2="нет"),"нет",AND(Y2=AA2,AC2="да"),"да",AND(Y2<>AA2,AC2="нет"),"да",AND(Y2<>AA2,AC2="да"),"нет")} -> нет | AA2: =VLOOKUP(B2,'Старый ИИ'!A:AQ,21,FALSE) -> Подтверждено | AB2: =VLOOKUP(B2,'Старый ИИ'!A:AQ,23,FALSE) -> Отчет подтверждает выполнение мероприятия: в пункте «19.12.2025 ФАУ «ФЦС» принял результат… – 100 нормативных требований переведены в машиночитаемый и машинопонимаемый XML‑формат и соответствуют методическому пособию (стр. 2). Плановое значение – перевод не менее 100 требований, также указано, что к 30.12.2025 будет размещено 100 требований в подсистеме «Реестр требований» (стр. 3). Таким образом, цель мероприятия полностью достигнута. | AC2: =VLOOKUP(B2,'Старый ИИ'!A:AQ,24,FALSE) -> да | AD2: =VLOOKUP(B2,'Старый ИИ'!A:AQ,25,FALSE) -> нет | AE2: =VLOOKUP(B2,'Старый ИИ'!A:AQ,26,FALSE) -> Корректно по статусу, но некорректно по анализируемой информации по ПХР, она не ровна нулю. | AF2: =VLOOKUP(B2,Общий!$E$2:$O$2000,10,0) -> 0 | AG2: =VLOOKUP(B2,Общий!$E$2:$O$2000,11,0) -> Единица | AH2: =VLOOKUP(B2,'Результат и ПХР'!$A$1:$M$992,13,0) -> Основой вывода выбран summary документа "Подтверждающие сведения 2.pdf". В evidence найдены действие "Переведены сведения", объект "содержащиеся в реестре требований, в машиночитаемый и машинопонимаемый формат" и прямой сигнал выполнения "подтверждающий готовность". Ключевой фрагмент evidence: "К письму прилагается акт от 10.12.2025, подтверждающий готовность доработанного функционала подсистемы «Реестр требований» и открытой части подсистемы «Официальный сайт» в составе ЕГИС «Стройкомплекс.РФ» к вводу в опытную эксплуатацию по результатам предварительных испытаний.". Этого достаточно для качественного подтверждения, поэтому статус мероприятия установлен как "подтверждено". | AI2: =VLOOKUP(B2,'Результат и ПХР'!$A$1:$T$992,6,0) -> подтверждено | AJ2: да | AK2: =VLOOKUP(B2,'Старый ИИ'!A:AQ,27,FALSE) -> Подтверждено | AL2: =VLOOKUP(B2,'Старый ИИ'!A:AQ,29,FALSE) -> В отчете указано, что результат достигнут в количестве 1 штука, что соответствует заявленному количеству единиц (1) мероприятия. Плановое значение в данных мероприятия указано как None, поэтому полное соответствие невозможно оценить полностью. | AM2: =VLOOKUP(B2,'Старый ИИ'!A:AQ,30,FALSE) -> да | AN2: =VLOOKUP(B2,'Старый ИИ'!A:AQ,31,FALSE) -> да | AO2: =VLOOKUP(B2,'Старый ИИ'!A:AQ,32,FALSE) -> -
A3: 9351224712 | B3: 9351225752 | C3: Организованы и проведены профориентационные образовательные отраслевые форумы для школьников, студентов и педагогов общеобразовательных организаций, колледжей и высших учебных заведений, и представителей крупнейших отраслевых компаний. | D3: Обеспечено взаимодействие студентов, педагогов и представителей отраслевых компаний, способствующее повышению компетенций молодежи, развитию и популяризации строительных профессий через практическое вовлечение, профориентацию и обмен опытом | E3: =VLOOKUP(B3,Подпись!$A$1:$E$100,5,0) -> #N/A | F3: =VLOOKUP(B3,Подпись!$A$1:$E$100,2,0) -> #N/A | G3: #N/A | H3: {=_xlfn.IFS(AND(G3=I3,K3="нет"),"нет",AND(G3=I3,K3="да"),"да",AND(G3<>I3,K3="нет"),"да",AND(G3<>I3,K3="да"),"нет")} -> #N/A | I3: =VLOOKUP(B3,'Старый ИИ'!A:AQ,3,FALSE) -> Не подтверждено | J3: =VLOOKUP(B3,'Старый ИИ'!A:AQ,5,FALSE) -> Найдены подписи: Бигава ГД, но они не совпадают с ответственными лицами | K3: =VLOOKUP(B3,'Старый ИИ'!A:AQ,6,FALSE) -> да | L3: =VLOOKUP(B3,'Старый ИИ'!A:AQ,7,FALSE) -> да | M3: =VLOOKUP(B3,'Старый ИИ'!A:AQ,8,FALSE) -> - | N3: Обеспечено взаимодействие студентов, педагогов и представителей отраслевых компаний, способствующее повышению компетенций молодежи, развитию и популяризации строительных профессий через практическое вовлечение, профориентацию и обмен опытом | O3: =VLOOKUP(A3,Характеристика!$A$1:$D$100,2,0) -> Подтверждающие сведения 1.pdf - Документ описывает проведение серии региональных форумов «Молодой специалист — строитель будущего». Эти форумы были направлены на повышение престижа строительных профессий и развитие ранней профориентации. Участие в мероприятиях включали школьников, студентов и представителей компаний-работодателей, что соответствует цели события. | P3: =VLOOKUP(A3,Характеристика!$A$1:$D$100,4,0) -> Подтверждено | Q3: {=_xlfn.IFS(AND(P3=R3,T3="нет"),"нет",AND(P3=R3,T3="да"),"да",AND(P3<>R3,T3="нет"),"да",AND(P3<>R3,T3="да"),"нет")} -> да | R3: =VLOOKUP(B3,'Старый ИИ'!A:AQ,9,FALSE) -> Подтверждено | S3: =VLOOKUP(B3,'Старый ИИ'!A:AQ,11,FALSE) -> Отчет подробно подтверждает проведение профориентционных отраслевых форумов для школьников, студентов, педагогов и представителей компаний: в разделе "Итоговый отчет о проведенных форумах" (стр. 3‑4) указано 14 форумов с более 12 000 участниками, в том числе 8 000+ студентов, 2 650+ школьников, 440 преподавателей и 360 представителей работодателей. Программа форумов (стр. 5) включает профориентационный трек для школьников, образовательный блок для студентов, секции для педагогов и формат для работодателей. Дополнительные результаты доступны по ссылке: https://prof.roskapstroy.ru/mery-podderzhki/rezultaty-issledovaniya/. | T3: =VLOOKUP(B3,'Старый ИИ'!A:AQ,12,FALSE) -> да | U3: =VLOOKUP(B3,'Старый ИИ'!A:AQ,13,FALSE) -> да | V3: =VLOOKUP(B3,'Старый ИИ'!A:AQ,14,FALSE) -> - | W3: =VLOOKUP(B3,'ПХР актуальный'!$A$1:$C$34,3,0) -> #NUM! | X3: =VLOOKUP(B3,'Результат и ПХР'!$A$1:$Q$992,14,0) -> Основой вывода выбран summary документа "Подтверждающие сведения 1.pdf". В evidence явно подтверждены метрика "Количество участников форумов", требуемая характеристика объекта и привязка количества к самому объекту метрики; зафиксировано значение 12000 человек. Ключевой фрагмент evidence: "В мероприятиях приняли участие более 12 000 человек, включая более 8 000 студентов, свыше 2 650 школьников, 440 преподавателей и 360 представителей компаний-работодателей.". Поэтому строгие правила ПХР выполнены, и итоговый статус установлен как "подтверждено". | Y3: =VLOOKUP(B3,'Результат и ПХР'!$A$1:$Q$992,7,0) -> подтверждено | Z3: {=_xlfn.IFS(AND(Y3=AA3,AC3="нет"),"нет",AND(Y3=AA3,AC3="да"),"да",AND(Y3<>AA3,AC3="нет"),"да",AND(Y3<>AA3,AC3="да"),"нет")} -> да | AA3: =VLOOKUP(B3,'Старый ИИ'!A:AQ,21,FALSE) -> Подтверждено | AB3: =VLOOKUP(B3,'Старый ИИ'!A:AQ,23,FALSE) -> Отчет детально подтверждает проведение профориентационных отраслевых форумов: на 14 форумах в 2025 г. (стр. 3‑4) приняло участие более 12 000 человек, включая >2 600 школьников, >8 000 студентов и 440 преподавателей, а также представителей компаний. Описаны конкретные города, количество участников и содержание программ (стр. 4‑5). Всё это полностью соответствует заявленному мероприятию. | AC3: =VLOOKUP(B3,'Старый ИИ'!A:AQ,24,FALSE) -> да | AD3: =VLOOKUP(B3,'Старый ИИ'!A:AQ,25,FALSE) -> нет | AE3: =VLOOKUP(B3,'Старый ИИ'!A:AQ,26,FALSE) -> Корректно по статусу, но некорректно по анализируемой информации по ПХР, она не ровна нулю | AF3: =VLOOKUP(B3,Общий!$E$2:$O$2000,10,0) -> 0 | AG3: =VLOOKUP(B3,Общий!$E$2:$O$2000,11,0) -> Единица | AH3: =VLOOKUP(B3,'Результат и ПХР'!$A$1:$M$992,13,0) -> Основой вывода выбран summary документа "Подтверждающие сведения 1.pdf". В evidence найдены действие "Организованы и проведены профориентационные образовательные отраслевые форумы для школьников", объект "студентов и педагогов общеобразовательных организаций, колледжей и высших учебных заведений, и представителей крупнейших отраслевых компаний." и прямой сигнал выполнения "итоговый отчет о проведении". Ключевой фрагмент evidence: "ФАУ «РосКапСтрой» представило в Минстрой России итоговый отчет о проведении в 2025 году серии региональных форумов «Молодой специалист — строитель будущего».". Этого достаточно для качественного подтверждения, поэтому статус мероприятия установлен как "подтверждено". | AI3: =VLOOKUP(B3,'Результат и ПХР'!$A$1:$T$992,6,0) -> подтверждено | AJ3: да | AK3: =VLOOKUP(B3,'Старый ИИ'!A:AQ,27,FALSE) -> Подтверждено | AL3: =VLOOKUP(B3,'Старый ИИ'!A:AQ,29,FALSE) -> Отчет подтверждает проведение 14 региональных форумов в 2025 г., соответствуя заявленной цели организации профориентационных мероприятий (см. раздел «Итоговый отчет…»). Подтверждение доступно в тексте и на сайте https://prof.roskapstroy.ru/mery-podderzhki/rezultaty-issledovaniya/. | AM3: =VLOOKUP(B3,'Старый ИИ'!A:AQ,30,FALSE) -> да | AN3: =VLOOKUP(B3,'Старый ИИ'!A:AQ,31,FALSE) -> нет | AO3: =VLOOKUP(B3,'Старый ИИ'!A:AQ,32,FALSE) -> Некорректно предоставлена информация ИИ в качестве планового значения - 0. В анализе ИИ пишет о корректном выполнении - 14.
A4: 9351223679 | B4: 9351224715 | C4: Обеспечено развитие подсистемы реестр документов и калькулятор мероприятий в системе "Стройкомплекс.РФ" | D4: Соотнесение сведений, содержащихся в реестре документов, сведений, материалов, согласований, предусмотренных нормативными правовыми актами Российской Федерации и необходимых застройщику, техническому заказчику для выполнения мероприятий при реализации проекта по строительству объекта капитального строительства с действующим нормативным правовым регулированием, а также доработка схем в калькуляторе реализации мероприятий, осуществляемых при реализации проектов по строительству объектов капитального строительства, направленных на расчет сроков реализации проектов по строительству ОКС применительно к конкретным ОКС | E4: =VLOOKUP(B4,Подпись!$A$1:$E$100,5,0) -> #N/A | F4: =VLOOKUP(B4,Подпись!$A$1:$E$100,2,0) -> #N/A | G4: #N/A | H4: {=_xlfn.IFS(AND(G4=I4,K4="нет"),"нет",AND(G4=I4,K4="да"),"да",AND(G4<>I4,K4="нет"),"да",AND(G4<>I4,K4="да"),"нет")} -> #N/A | I4: =VLOOKUP(B4,'Старый ИИ'!A:AQ,3,FALSE) -> Не подтверждено | J4: =VLOOKUP(B4,'Старый ИИ'!A:AQ,5,FALSE) -> Найдены подписи: Минстрой Р.З., Уважаемая О.А., В.Н. Медведев, но они не совпадают с ответственными лицами | K4: =VLOOKUP(B4,'Старый ИИ'!A:AQ,6,FALSE) -> да | L4: =VLOOKUP(B4,'Старый ИИ'!A:AQ,7,FALSE) -> да | M4: =VLOOKUP(B4,'Старый ИИ'!A:AQ,8,FALSE) -> - | N4: Соотнесение сведений, содержащихся в реестре документов, сведений, материалов, согласований, предусмотренных нормативными правовыми актами Российской Федерации и необходимых застройщику, техническому заказчику для выполнения мероприятий при реализации проекта по строительству объекта капитального строительства с действующим нормативным правовым регулированием, а также доработка схем в калькуляторе реализации мероприятий, осуществляемых при реализации проектов по строительству объектов капитального строительства, направленных на расчет сроков реализации проектов по строительству ОКС применительно к конкретным ОКС | O4: =VLOOKUP(A4,Характеристика!$A$1:$D$100,2,0) -> Подтверждающие сведения 1.pdf - Документ напрямую касается калькулятора реализации мероприятий в системе «Стройкомплекс.РФ». Упоминается количество схем в этом калькуляторе, что соответствует части описания события. Это подтверждает развитие и работу указанной подсистемы. | P4: =VLOOKUP(A4,Характеристика!$A$1:$D$100,4,0) -> Подтверждено | Q4: {=_xlfn.IFS(AND(P4=R4,T4="нет"),"нет",AND(P4=R4,T4="да"),"да",AND(P4<>R4,T4="нет"),"да",AND(P4<>R4,T4="да"),"нет")} -> да | R4: =VLOOKUP(B4,'Старый ИИ'!A:AQ,9,FALSE) -> Подтверждено | S4: =VLOOKUP(B4,'Старый ИИ'!A:AQ,11,FALSE) -> В отчёте указано, что в рамках мероприятия «Количество схем в калькуляторе мероприятий» в системе «Стройкомплекс.РФ» размещён калькулятор реализации мероприятий с 6 схемами (стр.1). Это подтверждает развитие подсистемы калькулятора мероприятий, однако сведения о подсистеме реестра документов отсутствуют, поэтому оценка не максимальна. | T4: =VLOOKUP(B4,'Старый ИИ'!A:AQ,12,FALSE) -> да | U4: =VLOOKUP(B4,'Старый ИИ'!A:AQ,13,FALSE) -> да | V4: =VLOOKUP(B4,'Старый ИИ'!A:AQ,14,FALSE) -> Корректно, подробности мероприятия предоставлены не все, но это не критично | W4: =VLOOKUP(B4,'ПХР актуальный'!$A$1:$C$34,3,0) -> #NUM! | X4: =VLOOKUP(B4,'Результат и ПХР'!$A$1:$Q$992,14,0) -> Основой вывода выбран ocr документа "Подтверждающие сведения 1.pdf". В evidence явно подтверждены метрика "Количество схем в реестре документов", требуемая характеристика объекта и привязка количества к самому объекту метрики; зафиксировано значение 6 Единица. Ключевой фрагмент evidence: "калькулятор реализации мероприятий, размещенный в единой государственной информационной системе обеспечения градостроительной деятельности «Стройкомплекс.РФ», содержит 6 схем". Поэтому строгие правила ПХР выполнены, и итоговый статус установлен как "подтверждено". | Y4: =VLOOKUP(B4,'Результат и ПХР'!$A$1:$Q$992,7,0) -> подтверждено | Z4: {=_xlfn.IFS(AND(Y4=AA4,AC4="нет"),"нет",AND(Y4=AA4,AC4="да"),"да",AND(Y4<>AA4,AC4="нет"),"да",AND(Y4<>AA4,AC4="да"),"нет")} -> да | AA4: =VLOOKUP(B4,'Старый ИИ'!A:AQ,21,FALSE) -> Подтверждено | AB4: =VLOOKUP(B4,'Старый ИИ'!A:AQ,23,FALSE) -> Отчет подтверждает развитие подсистемы: в нём указано, что калькулятор мероприятий в «Стройкомплекс.РФ» содержит 6 схем (стр. 1) – это согласуется с заявленным развитием калькулятора. Кроме того, в ПХР зафиксировано количество схем в реестре документов (1.0), что подтверждает наличие и развитие подсистемы реестра документов. Оба компонента мероприятия подтверждены документально. | AC4: =VLOOKUP(B4,'Старый ИИ'!A:AQ,24,FALSE) -> да | AD4: =VLOOKUP(B4,'Старый ИИ'!A:AQ,25,FALSE) -> нет | AE4: =VLOOKUP(B4,'Старый ИИ'!A:AQ,26,FALSE) -> Корректно по статусу, но некорректно по анализируемой информации по ПХР, она не ровна 1 (корректное значение - 3) | AF4: =VLOOKUP(B4,Общий!$E$2:$O$2000,10,0) -> 0 | AG4: =VLOOKUP(B4,Общий!$E$2:$O$2000,11,0) -> Единица | AH4: =VLOOKUP(B4,'Результат и ПХР'!$A$1:$M$992,13,0) -> Проверка опиралась на ocr документа "Подтверждающие сведения 1.pdf". В выбранном evidence не подтверждены следующие обязательные сигналы: обязательные сигналы. Имеющийся фрагмент "калькулятор реализации мероприятий, размещенный в единой государственной информационной системе обеспечения градостроительной деятельности «Стройкомплекс.РФ», содержит 6 схем" не дает прямого подтверждения выполнения. По правилу fail-closed статус мероприятия установлен как "не подтверждено". | AI4: =VLOOKUP(B4,'Результат и ПХР'!$A$1:$T$992,6,0) -> подтверждено | AJ4: да | AK4: =VLOOKUP(B4,'Старый ИИ'!A:AQ,27,FALSE) -> Не подтверждено | AL4: =VLOOKUP(B4,'Старый ИИ'!A:AQ,29,FALSE) -> Отчет фиксирует состояние калькулятора на конец декабря 2025 г., что частично соответствует требуемой дате 2025‑12‑31, однако точного указания «2025‑12‑31 00:00:00» нет, поэтому соответствие ограничено. | AM4: =VLOOKUP(B4,'Старый ИИ'!A:AQ,30,FALSE) -> нет | AN4: =VLOOKUP(B4,'Старый ИИ'!A:AQ,31,FALSE) -> нет | AO4: =VLOOKUP(B4,'Старый ИИ'!A:AQ,32,FALSE) -> Некорректно ИИ ищет точную дату подтверждения в подтверждении планового значения, а не сроков выполнения мероприятия. Фактическое значение 1 подтверждено.
A5: 9351224709 | B5: 9351224720 | C5: Реализованы проекты по повышению производительности труда в жилищно-коммунальном хозяйстве на базе отраслевого центра компетенций | D5: Центр компетенций реализует проекты по повышению производительности труда на предприятиях ЖКХ с использованием инструментов бережливого ЖКХ . Специалисты ОЦК, прошедшие обучение в АНО Федеральный центр компетенций в сфере производительности труда, проводят обучение представителей указанных организаций инструментам бережливого производства, которые позволят выстроить производственный процесс, создать решения по росту производительности труда за счёт устранения всех видов потерь, а также разработке корректирующих мероприятий для повышения эффективности. | E5: =VLOOKUP(B5,Подпись!$A$1:$E$100,5,0) -> Музыченко Сергей Григорьевич - Заместитель Министра, Файзуллин Ирек Энварович, Ломакин Александр Николаевич, Муценек Юрий Петрович, Стасишин Никита Евгеньевич, Гордеев Юрий Сергеевич, Музыченко Сергей Григорьевич, Михайлик Константин Александрович, Ересько Алексей Васильевич, Леонов Валерий Владимирович, Хусаинов Алмаз Шаукатович | F5: =VLOOKUP(B5,Подпись!$A$1:$E$100,2,0) -> Ересько Алексей Васильевич, Гордеев Юрий Сергеевич | G5: Подтверждено | H5: {=_xlfn.IFS(AND(G5=I5,K5="нет"),"нет",AND(G5=I5,K5="да"),"да",AND(G5<>I5,K5="нет"),"да",AND(G5<>I5,K5="да"),"нет")} -> нет | I5: =VLOOKUP(B5,'Старый ИИ'!A:AQ,3,FALSE) -> Не подтверждено | J5: =VLOOKUP(B5,'Старый ИИ'!A:AQ,5,FALSE) -> OCR обнаружил подписи, но анализ текста их не подтвердил. Возможно проблемы с качеством скана или распознаванием. | K5: =VLOOKUP(B5,'Старый ИИ'!A:AQ,6,FALSE) -> да | L5: =VLOOKUP(B5,'Старый ИИ'!A:AQ,7,FALSE) -> нет | M5: =VLOOKUP(B5,'Старый ИИ'!A:AQ,8,FALSE) -> ИИ корректно не принимает мероприятие - так как в документах стоит подпись не ответственного исполнителя, но в обосновании пишет о технической ошибке. Нет корректного обоснования какие подписи найдены. | N5: Центр компетенций реализует проекты по повышению производительности труда на предприятиях ЖКХ с использованием инструментов бережливого ЖКХ . Специалисты ОЦК, прошедшие обучение в АНО Федеральный центр компетенций в сфере производительности труда, проводят обучение представителей указанных организаций инструментам бережливого производства, которые позволят выстроить производственный процесс, создать решения по росту производительности труда за счёт устранения всех видов потерь, а также разработке корректирующих мероприятий для повышения эффективности. | O5: =VLOOKUP(A5,Характеристика!$A$1:$D$100,2,0) -> #N/A | P5: =VLOOKUP(A5,Характеристика!$A$1:$D$100,4,0) -> #N/A | Q5: {=_xlfn.IFS(AND(P5=R5,T5="нет"),"нет",AND(P5=R5,T5="да"),"да",AND(P5<>R5,T5="нет"),"да",AND(P5<>R5,T5="да"),"нет")} -> #N/A | R5: =VLOOKUP(B5,'Старый ИИ'!A:AQ,9,FALSE) -> Подтверждено | S5: =VLOOKUP(B5,'Старый ИИ'!A:AQ,11,FALSE) -> Отчет подтверждает реализацию проектов: указано, что целевые показатели достигнуты в полном объёме (пункт 1), разработано коробочное решение (1 ед.), описаны 10 лучших практик и проведено обучение 100 специалистов ЖКХ, что полностью соответствует заявленному мероприятию по повышению производительности труда в ЖКХ на базе отраслевого центра компетенций. | T5: =VLOOKUP(B5,'Старый ИИ'!A:AQ,12,FALSE) -> да | U5: =VLOOKUP(B5,'Старый ИИ'!A:AQ,13,FALSE) -> да | V5: =VLOOKUP(B5,'Старый ИИ'!A:AQ,14,FALSE) -> - | W5: =VLOOKUP(B5,'ПХР актуальный'!$A$1:$C$34,3,0) -> #NUM! | X5: =VLOOKUP(B5,'Результат и ПХР'!$A$1:$Q$992,14,0) -> #N/A | Y5: =VLOOKUP(B5,'Результат и ПХР'!$A$1:$Q$992,7,0) -> #N/A | Z5: {=_xlfn.IFS(AND(Y5=AA5,AC5="нет"),"нет",AND(Y5=AA5,AC5="да"),"да",AND(Y5<>AA5,AC5="нет"),"да",AND(Y5<>AA5,AC5="да"),"нет")} -> #N/A | AA5: =VLOOKUP(B5,'Старый ИИ'!A:AQ,21,FALSE) -> Подтверждено | AB5: =VLOOKUP(B5,'Старый ИИ'!A:AQ,23,FALSE) -> Отчет подтверждает реализацию проектов по повышению производительности труда в ЖКХ на базе отраслевого центра компетенций, о чём сказано в начале документа (стр. 1) и подтверждается перечислением достигнутых показателей: разработано 1 коробочное решение, описано 10 лучших практик, обучено 100 человек. Также указано, что проект отраслевой программы версии 2.0 разработан и передан в Минэкономразвития. Всё это полностью соответствует заявленному мероприятию. | AC5: =VLOOKUP(B5,'Старый ИИ'!A:AQ,24,FALSE) -> да | AD5: =VLOOKUP(B5,'Старый ИИ'!A:AQ,25,FALSE) -> нет | AE5: =VLOOKUP(B5,'Старый ИИ'!A:AQ,26,FALSE) -> ИИ некорректно описывает ПХР и ее количество, но корректно подтверждает ПХР. | AF5: =VLOOKUP(B5,Общий!$E$2:$O$2000,10,0) -> 0 | AG5: =VLOOKUP(B5,Общий!$E$2:$O$2000,11,0) -> Единица | AH5: =VLOOKUP(B5,'Результат и ПХР'!$A$1:$M$992,13,0) -> #N/A | AI5: =VLOOKUP(B5,'Результат и ПХР'!$A$1:$T$992,6,0) -> #N/A | AJ5: #N/A | AK5: =VLOOKUP(B5,'Старый ИИ'!A:AQ,27,FALSE) -> Подтверждено | AL5: =VLOOKUP(B5,'Старый ИИ'!A:AQ,29,FALSE) -> Отчет подтверждает реализацию мероприятия: в тексте указано разработка 1 коробочного решения, описание 10 лучших практик и обучение 100 специалистов, а также создание проекта программы версии 2.0 (см. раздел «Сообщаем, что целевые показатели…» и пункт о версии 2.0). Даты соответствуют 2025 году, требуемому сроку. | AM5: =VLOOKUP(B5,'Старый ИИ'!A:AQ,30,FALSE) -> да | AN5: =VLOOKUP(B5,'Старый ИИ'!A:AQ,31,FALSE) -> нет | AO5: =VLOOKUP(B5,'Старый ИИ'!A:AQ,32,FALSE) -> ИИ приводит некорректное плановое значение мероприятия. Корректное плановое значение мероприятия достигается в полном объеме.
A6: 9351224706 | B6: 9351225749 | C6: Реализованы проекты по повышению производительности труда с использованием инструментов бережливого проектирования и строительства на базе отраслевого центра компетенций | D6: Центр компетенций бережливого проектирования и строительства реализует проекты по повышению производительности труда с использованием инструментов бережливого строительства в средних и крупных проектно-строительных организациях. Специалисты ОЦК, прошедшие обучение в АНО Федеральный центр компетенций в сфере производительности труда, проводят обучение представителей указанных организаций инструментам бережливого производства, которые позволят выстроить производственный процесс, создать решения по росту производительности труда за счёт устранения всех видов потерь, а также разработке корректирующих мероприятий для повышения эффективности. | E6: =VLOOKUP(B6,Подпись!$A$1:$E$100,5,0) -> Музыченко Сергей Григорьевич - Заместитель Министра, Файзуллин Ирек Энварович, Ломакин Александр Николаевич, Муценек Юрий Петрович, Стасишин Никита Евгеньевич, Гордеев Юрий Сергеевич, Музыченко Сергей Григорьевич, Михайлик Константин Александрович, Ересько Алексей Васильевич, Леонов Валерий Владимирович, Хусаинов Алмаз Шаукатович | F6: =VLOOKUP(B6,Подпись!$A$1:$E$100,2,0) -> Музыченко Сергей Григорьевич | G6: Подтверждено | H6: {=_xlfn.IFS(AND(G6=I6,K6="нет"),"нет",AND(G6=I6,K6="да"),"да",AND(G6<>I6,K6="нет"),"да",AND(G6<>I6,K6="да"),"нет")} -> нет | I6: =VLOOKUP(B6,'Старый ИИ'!A:AQ,3,FALSE) -> Не подтверждено | J6: =VLOOKUP(B6,'Старый ИИ'!A:AQ,5,FALSE) -> Найдены подписи: Бигавва Г.Д., но они не совпадают с ответственными лицами | K6: =VLOOKUP(B6,'Старый ИИ'!A:AQ,6,FALSE) -> да | L6: =VLOOKUP(B6,'Старый ИИ'!A:AQ,7,FALSE) -> да | M6: =VLOOKUP(B6,'Старый ИИ'!A:AQ,8,FALSE) -> - | N6: Центр компетенций бережливого проектирования и строительства реализует проекты по повышению производительности труда с использованием инструментов бережливого строительства в средних и крупных проектно-строительных организациях. Специалисты ОЦК, прошедшие обучение в АНО Федеральный центр компетенций в сфере производительности труда, проводят обучение представителей указанных организаций инструментам бережливого производства, которые позволят выстроить производственный процесс, создать решения по росту производительности труда за счёт устранения всех видов потерь, а также разработке корректирующих мероприятий для повышения эффективности. | O6: =VLOOKUP(A6,Характеристика!$A$1:$D$100,2,0) -> Подтверждающие сведения 1.pdf - Документ описывает утверждение Положения об Отраслевом центре компетенций (ОЦК) по проектированию и строительству. Цели ОЦК прямо включают повышение производительности труда методами бережливого проектирования. Это соответствует теме реализации проектов по повышению производительности труда с использованием инструментов бережливого проектирования. Подтверждающие сведения 2.pdf - Документ упоминает реализацию проектов по повышению производительности труда на базе Отраслевого центра компетенций (ОЦК). Это напрямую соответствует теме события, где ОЦК реализует такие проекты. Также в тексте говорится о создании и запуске ОЦК, что является частью реализации указанных проектов. | P6: =VLOOKUP(A6,Характеристика!$A$1:$D$100,4,0) -> Подтверждено | Q6: {=_xlfn.IFS(AND(P6=R6,T6="нет"),"нет",AND(P6=R6,T6="да"),"да",AND(P6<>R6,T6="нет"),"да",AND(P6<>R6,T6="да"),"нет")} -> да | R6: =VLOOKUP(B6,'Старый ИИ'!A:AQ,9,FALSE) -> Не выполнено | S6: =VLOOKUP(B6,'Старый ИИ'!A:AQ,11,FALSE) -> 0 | T6: =VLOOKUP(B6,'Старый ИИ'!A:AQ,12,FALSE) -> нет | U6: =VLOOKUP(B6,'Старый ИИ'!A:AQ,13,FALSE) -> нет | V6: =VLOOKUP(B6,'Старый ИИ'!A:AQ,14,FALSE) -> Некорректно. Подтверждающий документ подтверждает суть описания мероприятия. | W6: =VLOOKUP(B6,'ПХР актуальный'!$A$1:$C$34,3,0) -> #NUM! | X6: =VLOOKUP(B6,'Результат и ПХР'!$A$1:$Q$992,14,0) -> Проверка опиралась на summary документа "Подтверждающие сведения 1.pdf". В выбранном evidence для метрики "Количество обученных специалистов отраслевого центра компетенций" установлено, что характеристика объекта не подтверждена явно; количество не привязано к объекту метрики; фактическое значение отсутствует; единица измерения отсутствует. Прямой подтверждающий фрагмент в evidence не найден. По правилу fail-closed статус ПХР установлен как "не подтверждено". | Y6: =VLOOKUP(B6,'Результат и ПХР'!$A$1:$Q$992,7,0) -> не подтверждено | Z6: {=_xlfn.IFS(AND(Y6=AA6,AC6="нет"),"нет",AND(Y6=AA6,AC6="да"),"да",AND(Y6<>AA6,AC6="нет"),"да",AND(Y6<>AA6,AC6="да"),"нет")} -> да | AA6: =VLOOKUP(B6,'Старый ИИ'!A:AQ,21,FALSE) -> Не выполнено | AB6: =VLOOKUP(B6,'Старый ИИ'!A:AQ,23,FALSE) -> 0 | AC6: =VLOOKUP(B6,'Старый ИИ'!A:AQ,24,FALSE) -> нет | AD6: =VLOOKUP(B6,'Старый ИИ'!A:AQ,25,FALSE) -> нет | AE6: =VLOOKUP(B6,'Старый ИИ'!A:AQ,26,FALSE) -> ИИ пишет о невыполнении количественной части характеристики, хотя у мероприятия нет характеристики с ненулевым плановым значением на 2025 год | AF6: =VLOOKUP(B6,Общий!$E$2:$O$2000,10,0) -> 0 | AG6: =VLOOKUP(B6,Общий!$E$2:$O$2000,11,0) -> Единица | AH6: =VLOOKUP(B6,'Результат и ПХР'!$A$1:$M$992,13,0) -> Проверка опиралась на summary документа "Подтверждающие сведения 1.pdf". В выбранном evidence не подтверждены следующие обязательные сигналы: действие, субъект, сигнал завершения. Прямой подтверждающий фрагмент в evidence не найден. По правилу fail-closed статус мероприятия установлен как "не подтверждено". | AI6: =VLOOKUP(B6,'Результат и ПХР'!$A$1:$T$992,6,0) -> не подтверждено | AJ6: нет | AK6: =VLOOKUP(B6,'Старый ИИ'!A:AQ,27,FALSE) -> Не выполнено | AL6: =VLOOKUP(B6,'Старый ИИ'!A:AQ,29,FALSE) -> 0 | AM6: =VLOOKUP(B6,'Старый ИИ'!A:AQ,30,FALSE) -> нет | AN6: =VLOOKUP(B6,'Старый ИИ'!A:AQ,31,FALSE) -> нет | AO6: =VLOOKUP(B6,'Старый ИИ'!A:AQ,32,FALSE) -> ИИ анализирует некорректное плановое значение, корректное плановое значение равно - 1. Подтверждающие документы говорят об утверждении положения об отраслевом центре компетенции
A7: 9187229902 | B7: 9187229922 | C7: Реализованы мероприятия по благоустройству общественных территорий (набережные, центральные площади, парки и др.) и иные мероприятия, предусмотренные государственными (муниципальными) программами формирования современной городской среды | D7: Ежегодно на территории муниципальных образований будут улучшены условия жизни граждан за счет создания качественных и современных общественных пространств, формирования новых возможностей для отдыха, занятия спортом, самореализации людей. | E7: =VLOOKUP(B7,Подпись!$A$1:$E$100,5,0) -> #N/A | F7: =VLOOKUP(B7,Подпись!$A$1:$E$100,2,0) -> #N/A | G7: #N/A | H7: {=_xlfn.IFS(AND(G7=I7,K7="нет"),"нет",AND(G7=I7,K7="да"),"да",AND(G7<>I7,K7="нет"),"да",AND(G7<>I7,K7="да"),"нет")} -> #N/A | I7: =VLOOKUP(B7,'Старый ИИ'!A:AQ,3,FALSE) -> Не подтверждено | J7: =VLOOKUP(B7,'Старый ИИ'!A:AQ,5,FALSE) -> Ошибка анализа: ошибка анализа | K7: =VLOOKUP(B7,'Старый ИИ'!A:AQ,6,FALSE) -> нет | L7: =VLOOKUP(B7,'Старый ИИ'!A:AQ,7,FALSE) -> нет | M7: =VLOOKUP(B7,'Старый ИИ'!A:AQ,8,FALSE) -> ИИ некорректно не принимает мероприятие - так как в документах стоит подпись ответственного исполнителя. | N7: Ежегодно на территории муниципальных образований будут улучшены условия жизни граждан за счет создания качественных и современных общественных пространств, формирования новых возможностей для отдыха, занятия спортом, самореализации людей. | O7: =VLOOKUP(A7,Характеристика!$A$1:$D$100,2,0) -> Подтверждающие сведения 1 (2).pdf - Документ содержит статистический отчет о количестве благоустроенных общественных территорий, таких как парки, набережные и центральные площади. Это напрямую соответствует теме реализации мероприятий по благоустройству общественных территорий, указанной в названии события. Также упоминается реализация мероприятий по формированию современной городской среды. | P7: =VLOOKUP(A7,Характеристика!$A$1:$D$100,4,0) -> Подтверждено | Q7: {=_xlfn.IFS(AND(P7=R7,T7="нет"),"нет",AND(P7=R7,T7="да"),"да",AND(P7<>R7,T7="нет"),"да",AND(P7<>R7,T7="да"),"нет")} -> да | R7: =VLOOKUP(B7,'Старый ИИ'!A:AQ,9,FALSE) -> Подтверждено | S7: =VLOOKUP(B7,'Старый ИИ'!A:AQ,11,FALSE) -> В отчёте (стр. 1) указаны разделы «Комплексное благоустройство общественных территорий… и иных мероприятий, предусмотренные государственными программами» и «Реализация мероприятий по благоустройству общественных территорий», подтверждающие реализацию описанных мероприятий. Таблицы на стр. 2‑4 содержат плановые и фактические показатели по регионам (пример — Республика Ингушетия, где отмечено 100 % выполнения), что соотносится с заявленными действиями по улучшению набережных, площадей и парков. | T7: =VLOOKUP(B7,'Старый ИИ'!A:AQ,12,FALSE) -> да | U7: =VLOOKUP(B7,'Старый ИИ'!A:AQ,13,FALSE) -> да | V7: =VLOOKUP(B7,'Старый ИИ'!A:AQ,14,FALSE) -> - | W7: Не указан | X7: =VLOOKUP(B7,'Результат и ПХР'!$A$1:$Q$992,14,0) -> Для мероприятия ПХР не задан в исходных данных. Поэтому doc-level проверка ПХР не запускалась и документы по ПХР не анализировались. Итоговый статус ПХР установлен как "не указано". | Y7: =VLOOKUP(B7,'Результат и ПХР'!$A$1:$Q$992,7,0) -> не указано | Z7: да | AA7: =VLOOKUP(B7,'Старый ИИ'!A:AQ,21,FALSE) -> Не применимо | AB7: =VLOOKUP(B7,'Старый ИИ'!A:AQ,23,FALSE) -> Анализ ПХР пропущен: показатели ПХР не указаны для данного мероприятия | AC7: =VLOOKUP(B7,'Старый ИИ'!A:AQ,24,FALSE) -> да | AD7: =VLOOKUP(B7,'Старый ИИ'!A:AQ,25,FALSE) -> да | AE7: =VLOOKUP(B7,'Старый ИИ'!A:AQ,26,FALSE) -> - | AF7: =VLOOKUP(B7,Общий!$E$2:$O$2000,10,0) -> 5000 | AG7: =VLOOKUP(B7,Общий!$E$2:$O$2000,11,0) -> Единица | AH7: =VLOOKUP(B7,'Результат и ПХР'!$A$1:$M$992,13,0) -> Проверка опиралась на summary документа "Подтверждающие сведения 1 (2).pdf". В выбранном evidence не подтверждены следующие обязательные сигналы: сигнал завершения, фактическое значение, единица измерения. Прямой подтверждающий фрагмент в evidence не найден. По правилу fail-closed статус мероприятия установлен как "не подтверждено". | AI7: =VLOOKUP(B7,'Результат и ПХР'!$A$1:$T$992,6,0) -> не подтверждено | AJ7: нет | AK7: =VLOOKUP(B7,'Старый ИИ'!A:AQ,27,FALSE) -> Подтверждено | AL7: =VLOOKUP(B7,'Старый ИИ'!A:AQ,29,FALSE) -> **1. Что удалось собрать:** - Подтверждено плановое значение: да. - Фактическое значение найдено в отчёте: да. - Фактическое значение соответствует плановому: да. - Вывод: плановое значение «23» полностью совпало с фактическим «23», показатель 100 % к плану, чек‑лист выполнен полностью. **2. Что не удалось собрать:** - Отсутствуют недостающие параметры – все необходимые сведения найдены и подтверждены. **3. Общий статус:** - Подтверждено выполнение планового значения: да. - Резюме: отчёт подтверждает полное выполнение запланированного объёма мероприятий для Республики Ингушетия. | AM7: =VLOOKUP(B7,'Старый ИИ'!A:AQ,30,FALSE) -> да | AN7: =VLOOKUP(B7,'Старый ИИ'!A:AQ,31,FALSE) -> нет | AO7: =VLOOKUP(B7,'Старый ИИ'!A:AQ,32,FALSE) -> ИИ сравнивал некорректное плановое значения с некорректным фактическим, но итоговый статус сошелся с правильным. | AP7: Плохой скан, не может быть прочитан
A8: 9187229901 | B8: 9187229919 | C8: Реализованы проекты победителей Всероссийского конкурса лучших проектов создания комфортной городской среды в малых городах и исторических поселениях (нарастающим итогом с 2025 г.) | D8: Ежегодно на территории победителей Всероссийского конкурса лучших проектов создания комфортной городской среды будут улучшены условия жизни граждан за счет создания качественных и современных общественных пространств, формирования новых возможностей для отдыха, занятия спортом, самореализации людей. | E8: =VLOOKUP(B8,Подпись!$A$1:$E$100,5,0) -> Ересько Алексей Васильевич - Заместитель Министра строительства и жилищно-коммунального хозяйства Российской Федерации, Файзуллин Ирек Энварович, Ломакин Александр Николаевич, Муценек Юрий Петрович, Стасишин Никита Евгеньевич, Гордеев Юрий Сергеевич, Музыченко Сергей Григорьевич, Михайлик Константин Александрович, Ересько Алексей Васильевич, Леонов Валерий Владимирович, Хусаинов Алмаз Шаукатович | F8: =VLOOKUP(B8,Подпись!$A$1:$E$100,2,0) -> Ересько Алексей Васильевич | G8: Подтверждено | H8: {=_xlfn.IFS(AND(G8=I8,K8="нет"),"нет",AND(G8=I8,K8="да"),"да",AND(G8<>I8,K8="нет"),"да",AND(G8<>I8,K8="да"),"нет")} -> да | I8: =VLOOKUP(B8,'Старый ИИ'!A:AQ,3,FALSE) -> Не подтверждено | J8: =VLOOKUP(B8,'Старый ИИ'!A:AQ,5,FALSE) -> Найдены подписи: Ереско А.В., но они не совпадают с ответственными лицами | K8: =VLOOKUP(B8,'Старый ИИ'!A:AQ,6,FALSE) -> нет | L8: =VLOOKUP(B8,'Старый ИИ'!A:AQ,7,FALSE) -> нет | M8: =VLOOKUP(B8,'Старый ИИ'!A:AQ,8,FALSE) -> ИИ пишет о найденной подписи ответственного исполнителя, но в статусе не подтверждает ее. | N8: Ежегодно на территории победителей Всероссийского конкурса лучших проектов создания комфортной городской среды будут улучшены условия жизни граждан за счет создания качественных и современных общественных пространств, формирования новых возможностей для отдыха, занятия спортом, самореализации людей. | O8: =VLOOKUP(A8,Характеристика!$A$1:$D$100,2,0) -> Подтверждающие сведения 1 (1).pdf - Документ представляет собой статистический отчет о реализации проектов победителей Всероссийского конкурса лучших проектов создания комфортной городской среды. Он содержит данные о количестве реализованных объектов, что напрямую связано с описанием события. Упоминается, что отчет составлен по состоянию на 31.12.2025, что соответствует временному контексту. | P8: =VLOOKUP(A8,Характеристика!$A$1:$D$100,4,0) -> Подтверждено | Q8: {=_xlfn.IFS(AND(P8=R8,T8="нет"),"нет",AND(P8=R8,T8="да"),"да",AND(P8<>R8,T8="нет"),"да",AND(P8<>R8,T8="да"),"нет")} -> да | R8: =VLOOKUP(B8,'Старый ИИ'!A:AQ,9,FALSE) -> Подтверждено | S8: =VLOOKUP(B8,'Старый ИИ'!A:AQ,11,FALSE) -> Отчет подтверждает, что реализованы проекты победителей Всероссийского конкурса по созданию комфортной городской среды (стр. 1, абз. «Reализованы проекты…», дата 31.12.2025). Таблицы 2‑4 содержат сведения о завершённых проектах в конкретных регионах (письма о завершении в г. Камышин, Поворино, Химки и др.) и показатели факта к плану, что соответствует заявленной цели мероприятия. | T8: =VLOOKUP(B8,'Старый ИИ'!A:AQ,12,FALSE) -> да | U8: =VLOOKUP(B8,'Старый ИИ'!A:AQ,13,FALSE) -> да | V8: =VLOOKUP(B8,'Старый ИИ'!A:AQ,14,FALSE) -> - | W8: Не указан | X8: =VLOOKUP(B8,'Результат и ПХР'!$A$1:$Q$992,14,0) -> Для мероприятия ПХР не задан в исходных данных. Поэтому doc-level проверка ПХР не запускалась и документы по ПХР не анализировались. Итоговый статус ПХР установлен как "не указано". | Y8: =VLOOKUP(B8,'Результат и ПХР'!$A$1:$Q$992,7,0) -> не указано | Z8: да | AA8: =VLOOKUP(B8,'Старый ИИ'!A:AQ,21,FALSE) -> Не применимо | AB8: =VLOOKUP(B8,'Старый ИИ'!A:AQ,23,FALSE) -> Анализ ПХР пропущен: показатели ПХР не указаны для данного мероприятия | AC8: =VLOOKUP(B8,'Старый ИИ'!A:AQ,24,FALSE) -> да | AD8: =VLOOKUP(B8,'Старый ИИ'!A:AQ,25,FALSE) -> да | AE8: =VLOOKUP(B8,'Старый ИИ'!A:AQ,26,FALSE) -> - | AF8: =VLOOKUP(B8,Общий!$E$2:$O$2000,10,0) -> 195 | AG8: =VLOOKUP(B8,Общий!$E$2:$O$2000,11,0) -> Единица | AH8: =VLOOKUP(B8,'Результат и ПХР'!$A$1:$M$992,13,0) -> Основой вывода выбран summary документа "Подтверждающие сведения 1 (1).pdf". В evidence найдены действие "Реализованы проекты победителей Всероссийского конкурса лучших проектов создания комфортной городской среды в малых городах и исторических поселениях", объект "нарастающим итогом с 2025 г.)", сигнал завершения "фактическое количество составило" и фактическое значение 246.0 проектов. Ключевой фрагмент evidence: "Согласно сводным данным, по Российской Федерации план в 195 объектов перевыполнен: фактическое количество составило 246 проектов (126,2%).". Сравнение результата определено как meets_target, поэтому статус мероприятия установлен как "подтверждено". | AI8: =VLOOKUP(B8,'Результат и ПХР'!$A$1:$T$992,6,0) -> подтверждено | AJ8: да | AK8: =VLOOKUP(B8,'Старый ИИ'!A:AQ,27,FALSE) -> Подтверждено | AL8: =VLOOKUP(B8,'Старый ИИ'!A:AQ,29,FALSE) -> В таблице первой страницы (строка «Центральный федеральный округ (в т. ч. Москва)») указано плановое значение 195 ед., а фактическое – 246 ед. за 2025 г. Это подтверждает заявленное значение мероприятия 195 ед. (план) и показывает превышение факта. | AM8: =VLOOKUP(B8,'Старый ИИ'!A:AQ,30,FALSE) -> да | AN8: =VLOOKUP(B8,'Старый ИИ'!A:AQ,31,FALSE) -> да | AO8: =VLOOKUP(B8,'Старый ИИ'!A:AQ,32,FALSE) -> -
A9: 9187604899 | B9: 9187604948 | C9: Обеспечена методологическая поддержка и информационно-аналитическое сопровождение реализации федерального проекта "Формирование комфортной городской среды" | D9: Обеспечение функций по управлению и сопровождению федерального проекта, оказание методического и консультационного сопровождения реализации федерального проекта, мониторинг реализации федерального проекта, достижение результатов федерального проекта. | E9: =VLOOKUP(B9,Подпись!$A$1:$E$100,5,0) -> #N/A | F9: =VLOOKUP(B9,Подпись!$A$1:$E$100,2,0) -> #N/A | G9: #N/A | H9: {=_xlfn.IFS(AND(G9=I9,K9="нет"),"нет",AND(G9=I9,K9="да"),"да",AND(G9<>I9,K9="нет"),"да",AND(G9<>I9,K9="да"),"нет")} -> #N/A | I9: =VLOOKUP(B9,'Старый ИИ'!A:AQ,3,FALSE) -> Не подтверждено | J9: =VLOOKUP(B9,'Старый ИИ'!A:AQ,5,FALSE) -> Найдены подписи: Зенкина О.Б., но они не совпадают с ответственными лицами | K9: =VLOOKUP(B9,'Старый ИИ'!A:AQ,6,FALSE) -> да | L9: =VLOOKUP(B9,'Старый ИИ'!A:AQ,7,FALSE) -> да | M9: =VLOOKUP(B9,'Старый ИИ'!A:AQ,8,FALSE) -> - | N9: Обеспечение функций по управлению и сопровождению федерального проекта, оказание методического и консультационного сопровождения реализации федерального проекта, мониторинг реализации федерального проекта, достижение результатов федерального проекта. | O9: =VLOOKUP(A9,Характеристика!$A$1:$D$100,2,0) -> Подтверждающие сведения 1.pdf - Текст напрямую касается реализации федерального проекта «Формирование комфортной городской среды». В нем упоминается подготовка аналитических отчетов и проведение конкурсов, что соответствует обеспечению информационно-аналитического сопровождения. Также в документе отражены результаты, что связано с мониторингом реализации проекта. | P9: =VLOOKUP(A9,Характеристика!$A$1:$D$100,4,0) -> Подтверждено | Q9: {=_xlfn.IFS(AND(P9=R9,T9="нет"),"нет",AND(P9=R9,T9="да"),"да",AND(P9<>R9,T9="нет"),"да",AND(P9<>R9,T9="да"),"нет")} -> да | R9: =VLOOKUP(B9,'Старый ИИ'!A:AQ,9,FALSE) -> Подтверждено | S9: =VLOOKUP(B9,'Старый ИИ'!A:AQ,11,FALSE) -> В отчете указано, что осуществляется сбор информации о ходе исполнения проектов, еженедельный мониторинг, подготовка аналитических отчетов «Светофор» и аналитики по победителям конкурсов — всё это подтверждает методологическую поддержку и информационно‑аналитическое сопровождение проекта «Формирование комфортной городской среды» (стр.1‑2). | T9: =VLOOKUP(B9,'Старый ИИ'!A:AQ,12,FALSE) -> да | U9: =VLOOKUP(B9,'Старый ИИ'!A:AQ,13,FALSE) -> да | V9: =VLOOKUP(B9,'Старый ИИ'!A:AQ,14,FALSE) -> - | W9: Не указан | X9: =VLOOKUP(B9,'Результат и ПХР'!$A$1:$Q$992,14,0) -> Для мероприятия ПХР не задан в исходных данных. Поэтому doc-level проверка ПХР не запускалась и документы по ПХР не анализировались. Итоговый статус ПХР установлен как "не указано". | Y9: =VLOOKUP(B9,'Результат и ПХР'!$A$1:$Q$992,7,0) -> не указано | Z9: да | AA9: =VLOOKUP(B9,'Старый ИИ'!A:AQ,21,FALSE) -> Не применимо | AB9: =VLOOKUP(B9,'Старый ИИ'!A:AQ,23,FALSE) -> Анализ ПХР пропущен: показатели ПХР не указаны для данного мероприятия | AC9: =VLOOKUP(B9,'Старый ИИ'!A:AQ,24,FALSE) -> да | AD9: =VLOOKUP(B9,'Старый ИИ'!A:AQ,25,FALSE) -> нет | AE9: =VLOOKUP(B9,'Старый ИИ'!A:AQ,26,FALSE) -> ИИ не проанализировал ПХР, хотя у мероприятия есть количественная ненулевая характеристика. По документам она выполнена. | AF9: =VLOOKUP(B9,Общий!$E$2:$O$2000,10,0) -> 1 | AG9: =VLOOKUP(B9,Общий!$E$2:$O$2000,11,0) -> Условная единица | AH9: =VLOOKUP(B9,'Результат и ПХР'!$A$1:$M$992,13,0) -> Проверка опиралась на ocr документа "Подтверждающие сведения 1.pdf". В выбранном evidence не подтверждены следующие обязательные сигналы: действие, субъект, сигнал завершения. Прямой подтверждающий фрагмент в evidence не найден. По правилу fail-closed статус мероприятия установлен как "не подтверждено". | AI9: =VLOOKUP(B9,'Результат и ПХР'!$A$1:$T$992,6,0) -> не подтверждено | AJ9: нет | AK9: =VLOOKUP(B9,'Старый ИИ'!A:AQ,27,FALSE) -> Подтверждено | AL9: =VLOOKUP(B9,'Старый ИИ'!A:AQ,29,FALSE) -> Отчет подтверждает выполнение мероприятия: подготовлены аналитические отчёты «Светофор» по реализации проекта (стр. 2) и по объектам победителей (стр. 2), а также осуществлён еженедельный мониторинг и сбор информации о ходе работ (стр. 1). Эти действия непосредственно соответствуют методологической поддержке и информационно‑аналитическому сопровождению проекта. | AM9: =VLOOKUP(B9,'Старый ИИ'!A:AQ,30,FALSE) -> да | AN9: =VLOOKUP(B9,'Старый ИИ'!A:AQ,31,FALSE) -> да | AO9: =VLOOKUP(B9,'Старый ИИ'!A:AQ,32,FALSE) -> -
A10: 9193757674 | B10: 9206711678 | C10: Приобретены с использованием Пушкинской карты билеты на посещение мероприятий (нарастающий итог) | D10: Целью мероприятия является создание условий для воспитания гармонично развитой и социально ответственной личности на основе духовно-нравственных ценностей народов Российской Федерации, исторических и национально-культурных традиций. В рамках мероприятия предоставляется возможность гражданам в возрасте с 14 до 22 лет воспользоваться программой социальной поддержки посещения учреждений культуры (театры, организации кинопоказа (кинотеатры), концертные организации, музеи, организации культурно-досугового типа, библиотеки и образовательные организации в сфере культуры).Реализация мероприятия способствует формированию художественного вкуса, кругозора в области культуры и искусства, а также привычки регулярно посещать мероприятия учреждений культуры у молодежи. | E10: =VLOOKUP(B10,Подпись!$A$1:$E$100,5,0) -> #N/A | F10: =VLOOKUP(B10,Подпись!$A$1:$E$100,2,0) -> #N/A | G10: #N/A | H10: {=_xlfn.IFS(AND(G10=I10,K10="нет"),"нет",AND(G10=I10,K10="да"),"да",AND(G10<>I10,K10="нет"),"да",AND(G10<>I10,K10="да"),"нет")} -> #N/A | I10: =VLOOKUP(B10,'Старый ИИ'!A:AQ,3,FALSE) -> Не подтверждено | J10: =VLOOKUP(B10,'Старый ИИ'!A:AQ,5,FALSE) -> Найдены подписи: Богданов С.Ю., но они не совпадают с ответственными лицами | K10: =VLOOKUP(B10,'Старый ИИ'!A:AQ,6,FALSE) -> да | L10: =VLOOKUP(B10,'Старый ИИ'!A:AQ,7,FALSE) -> да | M10: =VLOOKUP(B10,'Старый ИИ'!A:AQ,8,FALSE) -> - | N10: Целью мероприятия является создание условий для воспитания гармонично развитой и социально ответственной личности на основе духовно-нравственных ценностей народов Российской Федерации, исторических и национально-культурных традиций. В рамках мероприятия предоставляется возможность гражданам в возрасте с 14 до 22 лет воспользоваться программой социальной поддержки посещения учреждений культуры (театры, организации кинопоказа (кинотеатры), концертные организации, музеи, организации культурно-досугового типа, библиотеки и образовательные организации в сфере культуры).Реализация мероприятия способствует формированию художественного вкуса, кругозора в области культуры и искусства, а также привычки регулярно посещать мероприятия учреждений культуры у молодежи. | O10: =VLOOKUP(A10,Характеристика!$A$1:$D$100,2,0) -> Подтверждающие сведения 2.pdf - Документ содержит отчет об исполнении федерального проекта, связанного с программой «Пушкинская карта». В тексте прямо упоминается «нарастающее количество приобретенных билетов», что соответствует теме мероприятия. Это подтверждает реализацию программы, направленной на посещение учреждений культуры молодежью. | P10: =VLOOKUP(A10,Характеристика!$A$1:$D$100,4,0) -> Подтверждено | Q10: {=_xlfn.IFS(AND(P10=R10,T10="нет"),"нет",AND(P10=R10,T10="да"),"да",AND(P10<>R10,T10="нет"),"да",AND(P10<>R10,T10="да"),"нет")} -> да | R10: =VLOOKUP(B10,'Старый ИИ'!A:AQ,9,FALSE) -> Подтверждено | S10: =VLOOKUP(B10,'Старый ИИ'!A:AQ,11,FALSE) -> Отчет подтверждает достижение результата: на странице 1 указано фактическое значение «Приобретены с использованием Пушкинской карты билеты на посещение мероприятий» — 102,204 млн ед. (из них 22,06 млн ед. за 2025 год). Кроме того, в таблице (стр. 2) в строке «— Количество выданных билетов (шт.)» приведены кумулятивные цифры, достигающие 101 283 797 шт., что также свидетельствует о покупке билетов по карте. | T10: =VLOOKUP(B10,'Старый ИИ'!A:AQ,12,FALSE) -> да | U10: =VLOOKUP(B10,'Старый ИИ'!A:AQ,13,FALSE) -> да | V10: =VLOOKUP(B10,'Старый ИИ'!A:AQ,14,FALSE) -> - | W10: =VLOOKUP(B10,'ПХР актуальный'!$A$1:$C$34,3,0) -> #NUM! | X10: =VLOOKUP(B10,'Результат и ПХР'!$A$1:$Q$992,14,0) -> Основой вывода выбран ocr документа "Подтверждающие сведения 2.pdf". В evidence явно подтверждены метрика "Количество выданных Пушкинских карт", требуемая характеристика объекта и привязка количества к самому объекту метрики; зафиксировано значение 13.02 Миллион единиц. Ключевой фрагмент evidence: "по итогам 2025 года количество выданных Пушкинских карт составило 13,02 млн единиц.". Поэтому строгие правила ПХР выполнены, и итоговый статус установлен как "подтверждено". | Y10: =VLOOKUP(B10,'Результат и ПХР'!$A$1:$Q$992,7,0) -> подтверждено | Z10: {=_xlfn.IFS(AND(Y10=AA10,AC10="нет"),"нет",AND(Y10=AA10,AC10="да"),"да",AND(Y10<>AA10,AC10="нет"),"да",AND(Y10<>AA10,AC10="да"),"нет")} -> да | AA10: =VLOOKUP(B10,'Старый ИИ'!A:AQ,21,FALSE) -> Подтверждено | AB10: =VLOOKUP(B10,'Старый ИИ'!A:AQ,23,FALSE) -> Отчёт напрямую посвящён результату «Приобретены с использованием Пушкинской карты билеты на посещение мероприятий» (см. страница 1). В таблице указано количество выданных билетов к 31.12.2025 = 101 283 797 шт. (≈101,3 млн ед.), что подтверждает нарастающий итог мероприятия. | AC10: =VLOOKUP(B10,'Старый ИИ'!A:AQ,24,FALSE) -> да | AD10: =VLOOKUP(B10,'Старый ИИ'!A:AQ,25,FALSE) -> нет | AE10: =VLOOKUP(B10,'Старый ИИ'!A:AQ,26,FALSE) -> Корректно по статусу, но некорректно по анализу. ИИ соотносит некорректное количество ПХР. По документу все количественные части характеристики выполнены. | AF10: =VLOOKUP(B10,Общий!$E$2:$O$2000,10,0) -> 100.144 | AG10: =VLOOKUP(B10,Общий!$E$2:$O$2000,11,0) -> Миллион единиц | AH10: =VLOOKUP(B10,'Результат и ПХР'!$A$1:$M$992,13,0) -> Основой вывода выбран ocr документа "Подтверждающие сведения 2.pdf". В evidence найдены действие "Приобретены с использованием Пушкинской карты билеты на посещение мероприятий", объект "нарастающий итог)", сигнал завершения "фактическое значение" и фактическое значение 102.204 млн ед.. Ключевой фрагмент evidence: "фактическое значение (нарастающим итогом с начала реализации мероприятия) – 102,204 млн ед.". Сравнение результата определено как meets_target, поэтому статус мероприятия установлен как "подтверждено". | AI10: =VLOOKUP(B10,'Результат и ПХР'!$A$1:$T$992,6,0) -> подтверждено | AJ10: да | AK10: =VLOOKUP(B10,'Старый ИИ'!A:AQ,27,FALSE) -> Подтверждено | AL10: =VLOOKUP(B10,'Старый ИИ'!A:AQ,29,FALSE) -> В отчете указано плановое (нарастающее) значение 100,144 млн ед. и фактическое 102,204 млн ед. за 31.12.2025, что подтверждает заявленное значение мероприятия и даже превышает его (см. раздел «по состоянию на 31.12.2025»). | AM10: =VLOOKUP(B10,'Старый ИИ'!A:AQ,30,FALSE) -> да | AN10: =VLOOKUP(B10,'Старый ИИ'!A:AQ,31,FALSE) -> да | AO10: =VLOOKUP(B10,'Старый ИИ'!A:AQ,32,FALSE) -> -
A11: 9191447906 | B11: 9191447973 | C11: Оснащены современным оборудованием кинозалы в населенных пунктах до 500 тыс. человек, в которых обеспечен прокат национальных фильмов | D11: В рамках результата предусмотрено: 1) сохранение действующих условий мероприятия для новых субъектов Российской Федерации до достижения ими средних показателей уровня кинофикации (с 2025 по 2030 годы будут оснащены 90 кинозалов в населенных пунктах с численностью населения до 500 тыс. человек); 2) предоставление возможности приобретения за счет средств федерального бюджета мультимедийного оборудования населенным пунктам с численностью населения до 50 тыс. человек (с 2025 по 2030 годы будут оснащены 900 кинозалов); 3) приобретение комплектующих и расходных частей ранее поддержанным кинозалам (1 кинозал = 2,5 млн рублей): 2025 - 46 кинозалов, 2026 - 104, 2027- 120, 2028 - 46, 2029 - 52, 2030 - 56). | E11: =VLOOKUP(B11,Подпись!$A$1:$E$100,5,0) -> #N/A | F11: =VLOOKUP(B11,Подпись!$A$1:$E$100,2,0) -> #N/A | G11: #N/A | H11: {=_xlfn.IFS(AND(G11=I11,K11="нет"),"нет",AND(G11=I11,K11="да"),"да",AND(G11<>I11,K11="нет"),"да",AND(G11<>I11,K11="да"),"нет")} -> #N/A | I11: =VLOOKUP(B11,'Старый ИИ'!A:AQ,3,FALSE) -> Не подтверждено | J11: =VLOOKUP(B11,'Старый ИИ'!A:AQ,5,FALSE) -> Найдены подписи: Кокошкина Ю.К., Ярина А.А., но они не совпадают с ответственными лицами | K11: =VLOOKUP(B11,'Старый ИИ'!A:AQ,6,FALSE) -> да | L11: =VLOOKUP(B11,'Старый ИИ'!A:AQ,7,FALSE) -> да | M11: =VLOOKUP(B11,'Старый ИИ'!A:AQ,8,FALSE) -> - | N11: В рамках результата предусмотрено: 1) сохранение действующих условий мероприятия для новых субъектов Российской Федерации до достижения ими средних показателей уровня кинофикации (с 2025 по 2030 годы будут оснащены 90 кинозалов в населенных пунктах с численностью населения до 500 тыс. человек); 2) предоставление возможности приобретения за счет средств федерального бюджета мультимедийного оборудования населенным пунктам с численностью населения до 50 тыс. человек (с 2025 по 2030 годы будут оснащены 900 кинозалов); 3) приобретение комплектующих и расходных частей ранее поддержанным кинозалам (1 кинозал = 2,5 млн рублей): 2025 - 46 кинозалов, 2026 - 104, 2027- 120, 2028 - 46, 2029 - 52, 2030 - 56). | O11: =VLOOKUP(A11,Характеристика!$A$1:$D$100,2,0) -> Подтверждающие сведения 1.pdf - Документ содержит информацию о реализации программ по поддержке кинопоказов и развитию инфраструктуры. Упоминается открытие кинозалов в малых населенных пунктах и модификация оборудования кинозалов. Это соответствует теме оснащения кинозалов в населенных пунктах, указанной в описании события. Подтверждающие сведения 2.pdf - Событие касается оснащения кинозалов в населенных пунктах. В предоставленном тексте упоминается модернизация 51 кинозала и приобретение комплектующих и расходных материалов для 50 ранее поддержанных кинозалов. Это напрямую связано с деятельностью по поддержке и оснащению киноинфраструктуры. | P11: =VLOOKUP(A11,Характеристика!$A$1:$D$100,4,0) -> Подтверждено | Q11: {=_xlfn.IFS(AND(P11=R11,T11="нет"),"нет",AND(P11=R11,T11="да"),"да",AND(P11<>R11,T11="нет"),"да",AND(P11<>R11,T11="да"),"нет")} -> да | R11: =VLOOKUP(B11,'Старый ИИ'!A:AQ,9,FALSE) -> Подтверждено | S11: =VLOOKUP(B11,'Старый ИИ'!A:AQ,11,FALSE) -> Отчет подтверждает, что в 2025 г. открыты 10 кинозалов в населённых пунктах до 500 тыс. чел. (Стр. 1) с оборудованием, обеспечивающим прокат национальных фильмов, а также 41 центр в населённых пунктах до 50 тыс. чел. (Стр. 2) оснащены современным мультимедийным оборудованием, что полностью соответствует заявленному мероприятию. | T11: =VLOOKUP(B11,'Старый ИИ'!A:AQ,12,FALSE) -> да | U11: =VLOOKUP(B11,'Старый ИИ'!A:AQ,13,FALSE) -> да | V11: =VLOOKUP(B11,'Старый ИИ'!A:AQ,14,FALSE) -> - | W11: Не указан | X11: =VLOOKUP(B11,'Результат и ПХР'!$A$1:$Q$992,14,0) -> Для мероприятия ПХР не задан в исходных данных. Поэтому doc-level проверка ПХР не запускалась и документы по ПХР не анализировались. Итоговый статус ПХР установлен как "не указано". | Y11: =VLOOKUP(B11,'Результат и ПХР'!$A$1:$Q$992,7,0) -> не указано | Z11: да | AA11: =VLOOKUP(B11,'Старый ИИ'!A:AQ,21,FALSE) -> Не применимо | AB11: =VLOOKUP(B11,'Старый ИИ'!A:AQ,23,FALSE) -> Анализ ПХР пропущен: показатели ПХР не указаны для данного мероприятия | AC11: =VLOOKUP(B11,'Старый ИИ'!A:AQ,24,FALSE) -> да | AD11: =VLOOKUP(B11,'Старый ИИ'!A:AQ,25,FALSE) -> нет | AE11: =VLOOKUP(B11,'Старый ИИ'!A:AQ,26,FALSE) -> ИИ не проанализировал ПХР, хотя у мероприятия есть количественная ненулевая характеристика, которая подтверждена по документам. | AF11: =VLOOKUP(B11,Общий!$E$2:$O$2000,10,0) -> 1514 | AG11: =VLOOKUP(B11,Общий!$E$2:$O$2000,11,0) -> Единица | AH11: =VLOOKUP(B11,'Результат и ПХР'!$A$1:$M$992,13,0) -> Основой вывода выбран summary документа "Подтверждающие сведения 2.pdf". В evidence найдены действие "Оснащены современным оборудованием кинозалы в населенных пунктах до 500 тыс", объект "человек, в которых обеспечен прокат национальных фильмов", сигнал завершения "Нарастающим итогом с начала реализации проекта модернизировано" и фактическое значение 1515.0 кинозалов. Ключевой фрагмент evidence: "Нарастающим итогом с начала реализации проекта модернизировано 1 515 кинозалов.". Сравнение результата определено как meets_target, поэтому статус мероприятия установлен как "подтверждено". | AI11: =VLOOKUP(B11,'Результат и ПХР'!$A$1:$T$992,6,0) -> подтверждено | AJ11: да | AK11: =VLOOKUP(B11,'Старый ИИ'!A:AQ,27,FALSE) -> Подтверждено | AL11: =VLOOKUP(B11,'Старый ИИ'!A:AQ,29,FALSE) -> В отчете указано, что к 30.12.2025 г. модернизировано 1 515 кинозалов (стр. 2), что превышает запланированное значение 1 514 ед. (план). Факт полностью подтверждает KPI. | AM11: =VLOOKUP(B11,'Старый ИИ'!A:AQ,30,FALSE) -> да | AN11: =VLOOKUP(B11,'Старый ИИ'!A:AQ,31,FALSE) -> да | AO11: =VLOOKUP(B11,'Старый ИИ'!A:AQ,32,FALSE) -> -
